<?xml version="1.0"?>
<robot name="pedro_rescue" xmlns:xacro="http://www.ros.org/wiki/xacro">

  <!-- ══════════════════════════════════════════════
       Pedro's Rescue Robot — URDF/Xacro
       Differential drive · LDRobot LD19 · Orbbec RGB-D
       ══════════════════════════════════════════════ -->

  <!-- ── Propiedades físicas ── -->
  <xacro:property name="base_length"      value="0.35"/>   <!-- largo cuerpo [m] -->
  <xacro:property name="base_width"       value="0.35"/>   <!-- ancho cuerpo [m] -->
  <xacro:property name="base_height"      value="0.12"/>   <!-- alto cuerpo [m] -->
  <xacro:property name="base_mass"        value="5.0"/>    <!-- kg -->

  <xacro:property name="wheel_radius"     value="0.075"/>  <!-- radio rueda [m] -->
  <xacro:property name="wheel_width"      value="0.05"/>   <!-- ancho rueda [m] -->
  <xacro:property name="wheel_sep"        value="0.32"/>   <!-- separación entre ruedas [m] -->
  <xacro:property name="wheel_mass"       value="0.5"/>    <!-- kg -->

  <xacro:property name="lidar_radius"     value="0.04"/>   <!-- radio cilindro lidar [m] -->
  <xacro:property name="lidar_height"     value="0.04"/>   <!-- alto lidar [m] -->
  <xacro:property name="lidar_z_offset"   value="0.10"/>   <!-- altura desde tope de cuerpo [m] -->

  <!-- ── Materiales ── -->
  <material name="dark_gray"><color rgba="0.2 0.2 0.2 1.0"/></material>
  <material name="black">    <color rgba="0.1 0.1 0.1 1.0"/></material>
  <material name="blue">     <color rgba="0.1 0.3 0.9 1.0"/></material>
  <material name="white">    <color rgba="0.9 0.9 0.9 1.0"/></material>

  <!-- ══════════════════════════════════════════════
       BASE FOOTPRINT — referencia virtual en el suelo
       ══════════════════════════════════════════════ -->
  <link name="base_footprint"/>

  <joint name="base_footprint_to_base_link" type="fixed">
    <parent link="base_footprint"/>
    <child  link="base_link"/>
    <origin xyz="0 0 ${wheel_radius}" rpy="0 0 0"/>
  </joint>

  <!-- ══════════════════════════════════════════════
       BASE LINK — cuerpo principal del robot
       ══════════════════════════════════════════════ -->
  <link name="base_link">
    <visual>
      <origin xyz="0 0 0" rpy="0 0 0"/>
      <geometry>
        <box size="${base_length} ${base_width} ${base_height}"/>
      </geometry>
      <material name="dark_gray"/>
    </visual>
    <collision>
      <origin xyz="0 0 0" rpy="0 0 0"/>
      <geometry>
        <box size="${base_length} ${base_width} ${base_height}"/>
      </geometry>
    </collision>
    <inertial>
      <mass value="${base_mass}"/>
      <inertia
        ixx="${base_mass*(base_width*base_width + base_height*base_height)/12}"
        ixy="0" ixz="0"
        iyy="${base_mass*(base_length*base_length + base_height*base_height)/12}"
        iyz="0"
        izz="${base_mass*(base_length*base_length + base_width*base_width)/12}"/>
    </inertial>
  </link>

  <!-- ══════════════════════════════════════════════
       MACRO — rueda genérica
       ══════════════════════════════════════════════ -->
  <xacro:macro name="wheel" params="name y_offset">
    <link name="${name}_wheel">
      <visual>
        <origin xyz="0 0 0" rpy="${pi/2} 0 0"/>
        <geometry>
          <cylinder radius="${wheel_radius}" length="${wheel_width}"/>
        </geometry>
        <material name="black"/>
      </visual>
      <collision>
        <origin xyz="0 0 0" rpy="${pi/2} 0 0"/>
        <geometry>
          <cylinder radius="${wheel_radius}" length="${wheel_width}"/>
        </geometry>
      </collision>
      <inertial>
        <mass value="${wheel_mass}"/>
        <inertia
          ixx="${wheel_mass*(3*wheel_radius*wheel_radius + wheel_width*wheel_width)/12}"
          ixy="0" ixz="0"
          iyy="${wheel_mass*(3*wheel_radius*wheel_radius + wheel_width*wheel_width)/12}"
          iyz="0"
          izz="${wheel_mass*wheel_radius*wheel_radius/2}"/>
      </inertial>
    </link>

    <joint name="${name}_wheel_joint" type="continuous">
      <parent link="base_link"/>
      <child  link="${name}_wheel"/>
      <origin xyz="0 ${y_offset} ${-base_height/2}" rpy="0 0 0"/>
      <axis xyz="0 1 0"/>
      <dynamics damping="0.01" friction="0.1"/>
    </joint>
  </xacro:macro>

  <xacro:wheel name="left"  y_offset="${ wheel_sep/2}"/>
  <xacro:wheel name="right" y_offset="${-wheel_sep/2}"/>

  <!-- ══════════════════════════════════════════════
       RUEDA LOCA DELANTERA (caster)
       ══════════════════════════════════════════════ -->
  <link name="caster_link">
    <visual>
      <geometry>
        <sphere radius="${wheel_radius*0.5}"/>
      </geometry>
      <material name="black"/>
    </visual>
    <collision>
      <geometry>
        <sphere radius="${wheel_radius*0.5}"/>
      </geometry>
    </collision>
    <inertial>
      <mass value="0.2"/>
      <inertia ixx="0.001" ixy="0" ixz="0" iyy="0.001" iyz="0" izz="0.001"/>
    </inertial>
  </link>

  <joint name="caster_joint" type="fixed">
    <parent link="base_link"/>
    <child  link="caster_link"/>
    <origin xyz="${base_length/2 - 0.05} 0 ${-base_height/2 - wheel_radius*0.5}" rpy="0 0 0"/>
  </joint>

  <!-- ══════════════════════════════════════════════
       LIDAR — LDRobot LD19
       frame_id debe coincidir con ldlidar.yaml → 'ldlidar_link'
       ══════════════════════════════════════════════ -->
  <link name="ldlidar_link">
    <visual>
      <origin xyz="0 0 0" rpy="0 0 0"/>
      <geometry>
        <cylinder radius="${lidar_radius}" length="${lidar_height}"/>
      </geometry>
      <material name="blue"/>
    </visual>
    <collision>
      <geometry>
        <cylinder radius="${lidar_radius}" length="${lidar_height}"/>
      </geometry>
    </collision>
    <inertial>
      <mass value="0.15"/>
      <inertia ixx="0.0001" ixy="0" ixz="0" iyy="0.0001" iyz="0" izz="0.0001"/>
    </inertial>
  </link>

  <joint name="ldlidar_joint" type="fixed">
    <parent link="base_link"/>
    <child  link="ldlidar_link"/>
    <!-- centrado en la parte superior del cuerpo + offset de altura -->
    <origin xyz="0 0 ${base_height/2 + lidar_z_offset + lidar_height/2}" rpy="0 0 0"/>
  </joint>

  <!-- ══════════════════════════════════════════════
       CÁMARA — Orbbec (RGB-D)
       Montada en la parte delantera, inclinada hacia abajo 15°
       ══════════════════════════════════════════════ -->
  <link name="camera_link">
    <visual>
      <origin xyz="0 0 0" rpy="0 0 0"/>
      <geometry>
        <box size="0.04 0.09 0.03"/>
      </geometry>
      <material name="white"/>
    </visual>
    <inertial>
      <mass value="0.2"/>
      <inertia ixx="0.0001" ixy="0" ixz="0" iyy="0.0001" iyz="0" izz="0.0001"/>
    </inertial>
  </link>

  <joint name="camera_joint" type="fixed">
    <parent link="base_link"/>
    <child  link="camera_link"/>
    <origin xyz="${base_length/2 - 0.01} 0 ${base_height/2 + 0.05}"
            rpy="0 0.261 0"/>  <!-- 15° pitch down = 0.261 rad -->
  </joint>

  <!-- optical frame (convención ROS: x=right, y=down, z=forward) -->
  <link name="camera_optical_link"/>
  <joint name="camera_optical_joint" type="fixed">
    <parent link="camera_link"/>
    <child  link="camera_optical_link"/>
    <origin xyz="0 0 0" rpy="${-pi/2} 0 ${-pi/2}"/>
  </joint>

</robot>
